tests/golden/itch50/synthetic_minimal_diagnostic_snapshots.jsonl
{"asks":[null,null],"bids":[{"price4":1000000,"quantity":100},null],"book_digest":"7758963fe17316429adf944c70727208f076ae68102565b8c388d758af48085a","depth":2,"diagnostic_format":"itchlab-task-011-diagnostic-v1","event_kind":"add","event_price4":1000000,"event_quantity":100,"message_index":4,"stock_locate":1,"symbol":"AAPL","symbol_id":1,"timestamp_ns":34200000001000,"top_n_changed":true,"trading_state":"halted"}
{"asks":[null,null],"bids":[null,null],"book_digest":"47213ce72b18bbb9fb839f064fb00c71d810d21c19e1fe74a9ed61162c0d2a6c","depth":2,"diagnostic_format":"itchlab-task-011-diagnostic-v1","event_kind":"delete","event_price4":1000000,"event_quantity":100,"message_index":5,"stock_locate":1,"symbol":"AAPL","symbol_id":1,"timestamp_ns":34200000002000,"top_n_changed":true,"trading_state":"halted"}
